<?xml version="1.0" ?>
<!-- =================================================================================== -->
<!-- |    This document was autogenerated by xacro from kbot.urdf.xacro                | -->
<!-- |    EDITING THIS FILE BY HAND IS NOT RECOMMENDED                                 | -->
<!-- =================================================================================== -->
<robot name="kbot_arm" xmlns:xacro="http://ros.org/wiki/xacro">
  <!-- world frame -->
  <link name="world"/>
  <joint name="virtual_joint" type="fixed">
    <origin rpy="0 0 0" xyz="0 0 0"/>
    <parent link="world"/>
    <child link="base_link"/>
  </joint>
  <link name="base_link">
    <visual>
      <origin rpy="0 0 0" xyz="0 0 0"/>
      <geometry>
        <mesh filename="package://kbot_description/meshes/arm/visual/base_link.stl"/>
      </geometry>
    </visual>
    <collision>
      <origin rpy="0 0 0" xyz="0 0 0"/>
      <geometry>
        <mesh filename="package://kbot_description/meshes/arm/visual/base_link.stl"/>
      </geometry>
    </collision>
  </link>
  <link name="link_1">
    <inertial>
      <origin rpy="0 0 0" xyz="0 0 0"/>
      <mass value="0.019005"/>
      <inertia ixx="0" ixy="0" ixz="0" iyy="0" iyz="0" izz="0"/>
    </inertial>
    <visual>
      <origin rpy="0 0 0" xyz="0 0 0"/>
      <geometry>
        <mesh filename="package://kbot_description/meshes/arm/visual/proximal_arm_roll.stl"/>
      </geometry>
    </visual>
    <collision>
      <origin rpy="0 0 0" xyz="0 0 0"/>
      <geometry>
        <mesh filename="package://kbot_description/meshes/arm/visual/proximal_arm_roll.stl"/>
      </geometry>
    </collision>
  </link>
  <link name="link_2">
    <inertial>
      <origin rpy="0 0 0" xyz="-0.0925593094846925 -0.00915463972546963 -9.9500450073132E-17"/>
      <mass value="0.130669135830331"/>
      <inertia ixx="0" ixy="0" ixz="0" iyy="0" iyz="0" izz="0"/>
    </inertial>
    <visual>
      <origin rpy="0 0 0" xyz="0 0 0"/>
      <geometry>
        <mesh filename="package://kbot_description/meshes/arm/visual/proximal_arm_pitch.stl"/>
      </geometry>
    </visual>
    <collision>
      <origin rpy="0 0 0" xyz="0 0 0"/>
      <geometry>
        <mesh filename="package://kbot_description/meshes/arm/visual/proximal_arm_pitch.stl"/>
      </geometry>
    </collision>
  </link>
  <link name="link_3">
    <visual>
      <origin rpy="0 0 0" xyz="0 0 0"/>
      <geometry>
        <mesh filename="package://kbot_description/meshes/arm/visual/medial_arm_pitch.stl"/>
      </geometry>
    </visual>
    <collision>
      <origin rpy="0 0 0" xyz="0 0 0"/>
      <geometry>
        <mesh filename="package://kbot_description/meshes/arm/visual/medial_arm_pitch.stl"/>
      </geometry>
    </collision>
  </link>
  <link name="link_4">
    <visual>
      <origin rpy="0 0 0" xyz="0 0 0"/>
      <geometry>
        <mesh filename="package://kbot_description/meshes/arm/visual/medial_arm_roll.stl"/>
      </geometry>
    </visual>
    <collision>
      <origin rpy="0 0 0" xyz="0 0 0"/>
      <geometry>
        <mesh filename="package://kbot_description/meshes/arm/visual/medial_arm_roll.stl"/>
      </geometry>
    </collision>
  </link>
  <link name="link_5">
    <visual>
      <origin rpy="0 0 0" xyz="0 0 0"/>
      <geometry>
        <mesh filename="package://kbot_description/meshes/arm/visual/distal_arm_pitch.stl"/>
      </geometry>
    </visual>
    <collision>
      <origin rpy="0 0 0" xyz="0 0 0"/>
      <geometry>
        <mesh filename="package://kbot_description/meshes/arm/visual/distal_arm_pitch.stl"/>
      </geometry>
    </collision>
  </link>
  <link name="link_6">
    <visual>
      <origin rpy="0 0 0" xyz="0 0 0"/>
      <geometry>
        <mesh filename="package://kbot_description/meshes/arm/visual/distal_arm_roll.stl"/>
      </geometry>
    </visual>
    <collision>
      <origin rpy="0 0 0" xyz="0 0 0"/>
      <geometry>
        <mesh filename="package://kbot_description/meshes/arm/visual/distal_arm_roll.stl"/>
      </geometry>
    </collision>
  </link>
  <!-- joints: main serial chain -->
  <joint name="joint_1" type="revolute">
    <origin rpy="0 0 0" xyz="0 0 0.068"/>
    <parent link="base_link"/>
    <child link="link_1"/>
    <axis xyz="0 0 1"/>
    <limit effort="0" lower="-3.14159" upper="3.14159" velocity="3.67"/>
  </joint>
  <joint name="joint_2" type="revolute">
    <origin rpy="0 0 0" xyz="0 0 0.04448"/>
    <parent link="link_1"/>
    <child link="link_2"/>
    <axis xyz="0 1 0"/>
    <limit effort="0" lower="-2.15" upper="2.15" velocity="3.32"/>
  </joint>
  <joint name="joint_3" type="revolute">
    <origin rpy="0 0 0" xyz="0 0 0.18744"/>
    <parent link="link_2"/>
    <child link="link_3"/>
    <axis xyz="0 1 0"/>
    <limit effort="0" lower="-2.2" upper="2.05" velocity="3.67"/>
  </joint>
  <joint name="joint_4" type="revolute">
    <origin rpy="0 0 0" xyz="0 0 0.10293"/>
    <parent link="link_3"/>
    <child link="link_4"/>
    <axis xyz="0 0 1"/>
    <limit effort="0" lower="-3.14159" upper="3.14159" velocity="6.98"/>
  </joint>
  <joint name="joint_5" type="revolute">
    <origin rpy="0 0 0" xyz="0 0 0.08255"/>
    <parent link="link_4"/>
    <child link="link_5"/>
    <axis xyz="0 1 0"/>
    <limit effort="0" lower="-2" upper="2.3" velocity="6.98"/>
  </joint>
  <joint name="joint_6" type="revolute">
    <origin rpy="0 0 0" xyz="0 0 0.07675"/>
    <parent link="link_5"/>
    <child link="link_6"/>
    <axis xyz="0 0 1"/>
    <limit effort="0" lower="-3.14159" upper="3.14159" velocity="10.47"/>
  </joint>
  <!-- links: main serial chain -->
  <link name="palm">
    <visual>
      <origin rpy="0 0 0" xyz="0 0 0"/>
      <geometry>
        <mesh filename="package://kbot_description/meshes/gripper/visual/kbot_gripper_base.stl"/>
      </geometry>
    </visual>
    <collision>
      <origin rpy="0 0 0" xyz="0 0 0"/>
      <geometry>
        <mesh filename="package://kbot_description/meshes/gripper/visual/kbot_gripper_base.stl"/>
      </geometry>
    </collision>
  </link>
  <link name="left_outer_link">
    <visual>
      <origin rpy="0 0 0" xyz="0 0 0"/>
      <geometry>
        <mesh filename="package://kbot_description/meshes/gripper/visual/kbot_gripper_leftouterlink.stl"/>
      </geometry>
    </visual>
    <collision>
      <origin rpy="0 0 0" xyz="0 0 0"/>
      <geometry>
        <mesh filename="package://kbot_description/meshes/gripper/visual/kbot_gripper_leftouterlink.stl"/>
      </geometry>
    </collision>
  </link>
  <link name="left_inner_link">
    <visual>
      <origin rpy="0 0 0" xyz="0 0 0"/>
      <geometry>
        <mesh filename="package://kbot_description/meshes/gripper/visual/kbot_gripper_leftinnerlink.stl"/>
      </geometry>
    </visual>
    <collision>
      <origin rpy="0 0 0" xyz="0 0 0"/>
      <geometry>
        <mesh filename="package://kbot_description/meshes/gripper/visual/kbot_gripper_leftinnerlink.stl"/>
      </geometry>
    </collision>
  </link>
  <link name="left_finger">
    <visual>
      <origin rpy="0 0 0" xyz="0 0 0"/>
      <geometry>
        <mesh filename="package://kbot_description/meshes/gripper/visual/kbot_gripper_leftfinger.stl"/>
      </geometry>
    </visual>
    <collision>
      <origin rpy="0 0 0" xyz="0 0 0"/>
      <geometry>
        <mesh filename="package://kbot_description/meshes/gripper/visual/kbot_gripper_leftfinger.stl"/>
      </geometry>
    </collision>
  </link>
  <link name="right_outer_link">
    <visual>
      <origin rpy="0 0 0" xyz="0 0 0"/>
      <geometry>
        <mesh filename="package://kbot_description/meshes/gripper/visual/kbot_gripper_rightouterlink.stl"/>
      </geometry>
    </visual>
    <collision>
      <origin rpy="0 0 0" xyz="0 0 0"/>
      <geometry>
        <mesh filename="package://kbot_description/meshes/gripper/visual/kbot_gripper_rightouterlink.stl"/>
      </geometry>
    </collision>
  </link>
  <link name="right_inner_link">
    <visual>
      <origin rpy="0 0 0" xyz="0 0 0"/>
      <geometry>
        <mesh filename="package://kbot_description/meshes/gripper/visual/kbot_gripper_rightinnerlink.stl"/>
      </geometry>
    </visual>
    <collision>
      <origin rpy="0 0 0" xyz="0 0 0"/>
      <geometry>
        <mesh filename="package://kbot_description/meshes/gripper/visual/kbot_gripper_rightinnerlink.stl"/>
      </geometry>
    </collision>
  </link>
  <link name="right_finger">
    <visual>
      <origin rpy="0 0 0" xyz="0 0 0"/>
      <geometry>
        <mesh filename="package://kbot_description/meshes/gripper/visual/kbot_gripper_rightfinger.stl"/>
      </geometry>
    </visual>
    <collision>
      <origin rpy="0 0 0" xyz="0 0 0"/>
      <geometry>
        <mesh filename="package://kbot_description/meshes/gripper/visual/kbot_gripper_rightfinger.stl"/>
      </geometry>
    </collision>
  </link>
  <!-- joints: main serial chain -->
  <joint name="l_joint_0" type="revolute">
    <origin rpy="0 0 0" xyz="0 -0.0085 0.024"/>
    <parent link="palm"/>
    <child link="left_inner_link"/>
    <axis xyz="1 0 0"/>
    <limit effort="0" lower="0" upper="1.26" velocity="3.67"/>
  </joint>
  <joint name="l_joint_1" type="revolute">
    <origin rpy="0 0 0" xyz="0 -0.0265 0.016"/>
    <parent link="palm"/>
    <child link="left_outer_link"/>
    <axis xyz="1 0 0"/>
    <limit effort="0" lower="0" upper="1.26" velocity="3.67"/>
    <mimic joint="l_joint_0" multiplier="1" offset="0"/>
  </joint>
  <joint name="l_joint_2" type="revolute">
    <origin rpy="0 0 0" xyz="0 0 0.024"/>
    <parent link="left_inner_link"/>
    <child link="left_finger"/>
    <axis xyz="1 0 0"/>
    <limit effort="0" lower="0" upper="1.26" velocity="3.67"/>
    <mimic joint="l_joint_0" multiplier="-1" offset="0"/>
  </joint>
  <joint name="r_joint_0" type="revolute">
    <origin rpy="0 0 0" xyz="0 0.0085 0.024"/>
    <parent link="palm"/>
    <child link="right_inner_link"/>
    <axis xyz="1 0 0"/>
    <limit effort="0" lower="-1.26" upper="0" velocity="3.67"/>
  </joint>
  <joint name="r_joint_1" type="revolute">
    <origin rpy="0 0 0" xyz="0 0.0265 0.016"/>
    <parent link="palm"/>
    <child link="right_outer_link"/>
    <axis xyz="1 0 0"/>
    <limit effort="0" lower="0" upper="-1.26" velocity="3.67"/>
    <mimic joint="r_joint_0" multiplier="1" offset="0"/>
  </joint>
  <joint name="r_joint_2" type="revolute">
    <origin rpy="0 0 0" xyz="0 0 0.024"/>
    <parent link="right_inner_link"/>
    <child link="right_finger"/>
    <axis xyz="1 0 0"/>
    <limit effort="0" lower="0" upper="1.26" velocity="3.67"/>
    <mimic joint="r_joint_0" multiplier="-1" offset="0"/>
  </joint>
  <!-- tool 0 link to connect end effector -->
  <link name="tool0"/>
  <joint name="link_6-tool0" type="fixed">
    <origin rpy="0 0 0" xyz="0 0 0.02540"/>
    <parent link="link_6"/>
    <child link="tool0"/>
  </joint>
  <joint name="gripper_joint" type="fixed">
    <parent link="tool0"/>
    <child link="palm"/>
    <origin rpy="0 0 0" xyz="0 0 0"/>
  </joint>
</robot>
