<?xml version="1.0"?>
<robot xmlns:xacro="http://ros.org/wiki/xacro" name ="kbot_arm">

  <xacro:macro name="kbot_arm_" params="prefix">
    <!-- links: main serial chain -->
    <link name="${prefix}base_link">
      <visual>
        <origin xyz="0 0 0" rpy="0 0 0"/>
        <geometry>
          <mesh filename="package://kbot_arm/meshes/visual/base_link.stl"/>
        </geometry>
      </visual>
      <collision>
        <origin xyz="0 0 0" rpy="0 0 0"/>
        <geometry>
          <mesh filename="package://kbot_arm/meshes/visual/base_link.stl"/>
        </geometry>
      </collision>
    </link>

    <link name="${prefix}link_1">
      <inertial>
        <origin
	  xyz="0.024447 -0.021134 -1.8077E-17"
	  rpy="0 0 0" />
	<mass value="0.019005" />
	<inertia
	  ixx="0"
	  ixy="0"
	  ixz="0"
	  iyy="0"
	  iyz="0"
	  izz="0" />
      </inertial>
      <visual>
        <origin xyz="0 0 0" rpy="0 0 0"/>
        <geometry>
          <mesh filename="package://kbot_arm/meshes/visual/proximal_arm_roll.stl"/>
        </geometry>
      </visual>
      <collision>
        <origin xyz="0 0 0" rpy="0 0 0"/>
        <geometry>
          <mesh filename="package://kbot_arm/meshes/visual/proximal_arm_roll.stl"/>
        </geometry>
      </collision>
    </link>

    <link name="${prefix}link_2">
      <inertial>
        <origin
	  xyz="-0.0925593094846925 -0.00915463972546963 -9.9500450073132E-17"
	  rpy="0 0 0" />
	<mass value="0.130669135830331" />
	<inertia
	  ixx="0"
	  ixy="0"
	  ixz="0"
	  iyy="0"
	  iyz="0"
	  izz="0" />
      </inertial>
      <visual>
        <origin xyz="0 0 0" rpy="0 0 0"/>
        <geometry>
          <mesh filename="package://kbot_arm/meshes/visual/proximal_arm_pitch.stl"/>
        </geometry>
      </visual>
      <collision>
        <origin xyz="0 0 0" rpy="0 0 0"/>
        <geometry>
          <mesh filename="package://kbot_arm/meshes/visual/proximal_arm_pitch.stl"/>
        </geometry>
      </collision>
    </link>

    <link name="${prefix}link_3">
      <visual>
        <origin xyz="0 0 0" rpy="0 0 0"/>
        <geometry>
          <mesh filename="package://kbot_arm/meshes/visual/medial_arm_pitch.stl"/>
        </geometry>
      </visual>
      <collision>
        <origin xyz="0 0 0" rpy="0 0 0"/>
        <geometry>
          <mesh filename="package://kbot_arm/meshes/visual/medial_arm_pitch.stl"/>
        </geometry>
      </collision>
    </link>

    <link name="${prefix}link_4">
      <visual>
        <origin xyz="0 0 0" rpy="0 0 0"/>
        <geometry>
          <mesh filename="package://kbot_arm/meshes/visual/medial_arm_roll.stl"/>
        </geometry>
      </visual>
      <collision>
        <origin xyz="0 0 0" rpy="0 0 0"/>
        <geometry>
          <mesh filename="package://kbot_arm/meshes/visual/medial_arm_roll.stl"/>
        </geometry>
      </collision>
    </link>

    <link name="${prefix}link_5">
      <visual>
        <origin xyz="0 0 0" rpy="0 0 0"/>
        <geometry>
          <mesh filename="package://kbot_arm/meshes/visual/distal_arm_pitch.stl"/>
        </geometry>
      </visual>
      <collision>
        <origin xyz="0 0 0" rpy="0 0 0"/>
        <geometry>
          <mesh filename="package://kbot_arm/meshes/visual/distal_arm_pitch.stl"/>
        </geometry>
      </collision>
    </link>

    <link name="${prefix}link_6">
      <visual>
        <origin xyz="0 0 0" rpy="0 0 0"/>
        <geometry>
          <mesh filename="package://kbot_arm/meshes/visual/distal_arm_roll.stl"/>
        </geometry>
      </visual>
      <collision>
        <origin xyz="0 0 0" rpy="0 0 0"/>
        <geometry>
          <mesh filename="package://kbot_arm/meshes/visual/distal_arm_roll.stl"/>
        </geometry>
      </collision>
    </link>

    <!-- joints: main serial chain -->
    <joint name="${prefix}joint_1" type="revolute">
      <origin xyz="0 0 0.068" rpy="0 0 0"/>
      <parent link="${prefix}base_link"/>
      <child link="${prefix}link_1"/>
      <axis xyz="0 0 1"/>
      <limit lower="-3.14159" upper="3.14159" effort="0" velocity="3.67"/>
    </joint>
    <joint name="${prefix}joint_2" type="revolute">
      <origin xyz="0 0 0.04448" rpy="0 0 0"/>
      <parent link="${prefix}link_1"/>
      <child link="${prefix}link_2"/>
      <axis xyz="0 1 0"/>
      <limit lower="-2.15" upper="2.15" effort="0" velocity="3.32"/>
    </joint>
    <joint name="${prefix}joint_3" type="revolute">
      <origin xyz="0 0 0.18744" rpy="0 0 0"/>
      <parent link="${prefix}link_2"/>
      <child link="${prefix}link_3"/>
      <axis xyz="0 1 0"/>
      <limit lower="-2.2" upper="2.05" effort="0" velocity="3.67"/>
    </joint>
    <joint name="${prefix}joint_4" type="revolute">
      <origin xyz="0 0 0.10293" rpy="0 0 0"/>
      <parent link="${prefix}link_3"/>
      <child link="${prefix}link_4"/>
      <axis xyz="0 0 1"/>
      <limit lower="-3.14159" upper="3.14159" effort="0" velocity="6.98"/>
    </joint>
    <joint name="${prefix}joint_5" type="revolute">
      <origin xyz="0 0 0.08255" rpy="0 0 0"/>
      <parent link="${prefix}link_4"/>
      <child link="${prefix}link_5"/>
      <axis xyz="0 1 0"/>
      <limit lower="-2" upper="2.3" effort="0" velocity="6.98"/>
    </joint>
    <joint name="${prefix}joint_6" type="revolute">
      <origin xyz="0 0 0.07675" rpy="0 0 0"/>
      <parent link="${prefix}link_5"/>
      <child link="${prefix}link_6"/>
      <axis xyz="0 0 1"/>
      <limit lower="-3.14159" upper="3.14159" effort="0" velocity="10.47"/>
    </joint>

    <!-- ROS-Industrial 'base' frame: base_link to Fanuc World Coordinates transform -->
    <link name="${prefix}world"/>
    <joint name="${prefix}base_joint" type="fixed">
      <origin xyz="0 0 0" rpy="0 0 0"/>
      <parent link="${prefix}world"/>
      <child link="${prefix}base_link"/>
    </joint>
       
    <!-- ROS-Industrial 'flange' frame: attachment point for EEF models
    <link name="${prefix}flange" />
    <joint name="${prefix}joint_6-flange" type="fixed">
      <origin xyz="0 0 0" rpy="0 0 0" />
      <parent link="${prefix}link_6" />
      <child link="${prefix}flange" />
    </joint>-->

    <!-- ROS-Industrial 'tool0' frame: all-zeros tool frame -->
    <link name="${prefix}tool0" />
    <joint name="${prefix}link_6-tool0" type="fixed">
      <origin xyz="0 0 0.02540" rpy="0 0 0" />
      <parent link="${prefix}link_6" />
      <child link="${prefix}tool0" />
    </joint>
  </xacro:macro>
</robot>
