<?xml version="1.0" ?>
<!-- =================================================================================== -->
<!-- |    This document was autogenerated by xacro from kbot_gripper.xacro             | -->
<!-- |    EDITING THIS FILE BY HAND IS NOT RECOMMENDED                                 | -->
<!-- =================================================================================== -->
<robot name="kbot_gripper" xmlns:xacro="http://ros.org/wiki/xacro">
  <!-- links: main serial chain -->
  <link name="base_link">
    <visual>
      <origin rpy="0 0 0" xyz="0 0 0"/>
      <geometry>
        <mesh filename="package://kbot_arm/meshes//gripper/visual/kbot_gripper_base.stl"/>
      </geometry>
    </visual>
    <collision>
      <origin rpy="0 0 0" xyz="0 0 0"/>
      <geometry>
        <mesh filename="package://kbot_arm/meshes//gripper/visual/kbot_gripper_base.stl"/>
      </geometry>
    </collision>
  </link>
  <link name="left_outer_link">
    <visual>
      <origin rpy="0 0 0" xyz="0 0 0"/>
      <geometry>
        <mesh filename="package://kbot_arm/meshes/gripper/visual/kbot_gripper_leftouterlink.stl"/>
      </geometry>
    </visual>
    <collision>
      <origin rpy="0 0 0" xyz="0 0 0"/>
      <geometry>
        <mesh filename="package://kbot_arm/meshes/gripper/visual/kbot_gripper_leftouterlink.stl"/>
      </geometry>
    </collision>
  </link>
  <link name="left_inner_link">
    <visual>
      <origin rpy="0 0 0" xyz="0 0 0"/>
      <geometry>
        <mesh filename="package://kbot_arm/meshes/gripper/visual/kbot_gripper_leftinnerlink.stl"/>
      </geometry>
    </visual>
    <collision>
      <origin rpy="0 0 0" xyz="0 0 0"/>
      <geometry>
        <mesh filename="package://kbot_arm/meshes/gripper/visual/kbot_gripper_leftinnerlink.stl"/>
      </geometry>
    </collision>
  </link>
  <link name="left_finger">
    <visual>
      <origin rpy="0 0 0" xyz="0 0 0"/>
      <geometry>
        <mesh filename="package://kbot_arm/meshes/gripper/visual/kbot_gripper_leftfinger.stl"/>
      </geometry>
    </visual>
    <collision>
      <origin rpy="0 0 0" xyz="0 0 0"/>
      <geometry>
        <mesh filename="package://kbot_arm/meshes/gripper/visual/kbot_gripper_leftfinger.stl"/>
      </geometry>
    </collision>
  </link>
  <link name="right_outer_link">
    <visual>
      <origin rpy="0 0 0" xyz="0 0 0"/>
      <geometry>
        <mesh filename="package://kbot_arm/meshes/gripper/visual/kbot_gripper_rightouterlink.stl"/>
      </geometry>
    </visual>
    <collision>
      <origin rpy="0 0 0" xyz="0 0 0"/>
      <geometry>
        <mesh filename="package://kbot_arm/meshes/gripper/visual/kbot_gripper_rightouterlink.stl"/>
      </geometry>
    </collision>
  </link>
  <link name="right_inner_link">
    <visual>
      <origin rpy="0 0 0" xyz="0 0 0"/>
      <geometry>
        <mesh filename="package://kbot_arm/meshes/gripper/visual/kbot_gripper_rightinnerlink.stl"/>
      </geometry>
    </visual>
    <collision>
      <origin rpy="0 0 0" xyz="0 0 0"/>
      <geometry>
        <mesh filename="package://kbot_arm/meshes/gripper/visual/kbot_gripper_rightinnerlink.stl"/>
      </geometry>
    </collision>
  </link>
  <link name="right_finger">
    <visual>
      <origin rpy="0 0 0" xyz="0 0 0"/>
      <geometry>
        <mesh filename="package://kbot_arm/meshes/gripper/visual/kbot_gripper_rightfinger.stl"/>
      </geometry>
    </visual>
    <collision>
      <origin rpy="0 0 0" xyz="0 0 0"/>
      <geometry>
        <mesh filename="package://kbot_arm/meshes/gripper/visual/kbot_gripper_rightfinger.stl"/>
      </geometry>
    </collision>
  </link>
  <!-- joints: main serial chain -->
  <joint name="l_joint_0" type="revolute">
    <origin rpy="0 0 0" xyz="0 -0.0085 0.024"/>
    <parent link="base_link"/>
    <child link="left_inner_link"/>
    <axis xyz="1 0 0"/>
    <limit effort="0" lower="0" upper="1.26" velocity="3.67"/>
  </joint>
  <joint name="l_joint_1" type="revolute">
    <origin rpy="0 0 0" xyz="0 -0.0265 0.016"/>
    <parent link="base_link"/>
    <child link="left_outer_link"/>
    <axis xyz="1 0 0"/>
    <limit effort="0" lower="0" upper="1.26" velocity="3.67"/>
    <mimic joint="l_joint_0" multiplier="1" offset="0"/>
  </joint>
  <joint name="l_joint_2" type="revolute">
    <origin rpy="0 0 0" xyz="0 0 0.024"/>
    <parent link="left_inner_link"/>
    <child link="left_finger"/>
    <axis xyz="1 0 0"/>
    <limit effort="0" lower="0" upper="1.26" velocity="3.67"/>
    <mimic joint="l_joint_0" multiplier="-1" offset="0"/>
  </joint>
  <joint name="r_joint_0" type="revolute">
    <origin rpy="0 0 0" xyz="0 0.0085 0.024"/>
    <parent link="base_link"/>
    <child link="right_inner_link"/>
    <axis xyz="1 0 0"/>
    <limit effort="0" lower="-1.26" upper="0" velocity="3.67"/>
  </joint>
  <joint name="r_joint_1" type="revolute">
    <origin rpy="0 0 0" xyz="0 0.0265 0.016"/>
    <parent link="base_link"/>
    <child link="right_outer_link"/>
    <axis xyz="1 0 0"/>
    <limit effort="0" lower="0" upper="-1.26" velocity="3.67"/>
    <mimic joint="r_joint_0" multiplier="1" offset="0"/>
  </joint>
  <joint name="r_joint_2" type="revolute">
    <origin rpy="0 0 0" xyz="0 0 0.024"/>
    <parent link="right_inner_link"/>
    <child link="right_finger"/>
    <axis xyz="1 0 0"/>
    <limit effort="0" lower="0" upper="1.26" velocity="3.67"/>
    <mimic joint="r_joint_0" multiplier="-1" offset="0"/>
  </joint>
  <!-- ROS-Industrial 'base' frame: base_link to Fanuc World Coordinates transform 
    <link name="${prefix}base" />
    <joint name="${prefix}base_link-base" type="fixed">
      <origin xyz="0 0 0" rpy="0 0 0"/>
      <parent link="${prefix}base_link"/>
      <child link="${prefix}base"/>
    </joint> -->
  <!-- ROS-Industrial 'flange' frame: attachment point for EEF models
    <link name="${prefix}flange" />
    <joint name="${prefix}joint_6-flange" type="fixed">
      <origin xyz="0 0 0" rpy="0 0 0" />
      <parent link="${prefix}link_6" />
      <child link="${prefix}flange" />
    </joint>
-->
  <!-- ROS-Industrial 'tool0' frame: all-zeros tool frame 
    <link name="${prefix}tool0" />
    <joint name="${prefix}link_6-tool0" type="fixed">
      <origin xyz="0 0 0" rpy="0 0 0" />
      <parent link="${prefix}link_6" />
      <child link="${prefix}tool0" />
    </joint>-->
</robot>
